Workbook

Sheet Graduated Pricing
B2: PIXI — Graduated (Tax-Bracket) Pricing
B3: ✓ PIXI's ADOPTED pricing model. First 3 hotels at full price; each higher bracket bills a lower MARGINAL rate (like income tax). Cliff-free — quote customers the blended rate + total.
B5: SHARED ASSUMPTIONS (pulled live from 'Pricing Model')
B6: Base / hotel 1–3 (£/mo, annual-paid) | C6: ='Pricing Model'!$C$6 -> 99
B7: Cost to serve / hotel / mo (£) | C7: ='Pricing Model'!$C$10 -> 20 | D7: *based on AWS costs
B8: Monthly-billing uplift | C8: ='Pricing Model'!$C$8 -> 0.15
B9: Legacy benchmark / hotel / mo | C9: ='Pricing Model'!$C$9 -> 170
B10: Margin floor — flag below | C10: ='Pricing Model'!$C$11 -> 0.6
B11: Pro anchor (hotel 1–3) £/mo | C11: 299
B12: GRADUATED BRACKETS (marginal £/hotel — blue = edit; bracket 1 = full price)
B13: Bracket | C13: Hotels from | D13: Hotels to | E13: Marginal £/hotel/mo | F13: Marginal margin % | G13: Pro marginal £/hotel/mo | H13: Pro margin %
B14: 1 | C14: 1 | D14: 3 | E14: =$C$6 -> 99 | F14: =1-$C$7/E14 -> 0.7979798 | G14: =E14*$C$11/$C$6 -> 299 | H14: =1-$C$7/G14 -> 0.93311037
B15: 2 | C15: 4 | D15: 15 | E15: 79 | F15: =1-$C$7/E15 -> 0.74683544 | G15: =E15*$C$11/$C$6 -> 238.59596 | H15: =1-$C$7/G15 -> 0.91617628
B16: 3 | C16: 16 | D16: 30 | E16: 69 | F16: =1-$C$7/E16 -> 0.71014493 | G16: =E16*$C$11/$C$6 -> 208.39394 | H16: =1-$C$7/G16 -> 0.90402792
B17: 4 | C17: 31 | D17: 50 | E17: 59 | F17: =1-$C$7/E17 -> 0.66101695 | G17: =E17*$C$11/$C$6 -> 178.19192 | H17: =1-$C$7/G17 -> 0.88776146
B18: 5 | C18: 51 | D18: 9999 | E18: 49 | F18: =1-$C$7/E18 -> 0.59183673 | G18: =E18*$C$11/$C$6 -> 147.9899 | H18: =1-$C$7/G18 -> 0.86485564
B19: Marginal margin = profit on each hotel IN that bracket. Blended margin (all hotels) is higher — see scenarios.
B21: QUOTE CALCULATOR
B22: Number of hotels in deal | C22: 1
B24: Bracket | C24: Range | D24: Marginal £ | E24: Hotels in bracket | F24: Subtotal /mo | G24: Yearly | H24: Pro marginal £ | I24: Pro subtotal per month | J24: Yearly
B25: =B14 -> 1 | C25: =C14&"–"&IF(D14>=9999,"+",D14) -> 1–3 | D25: =E14 -> 99 | E25: =MAX(0,MIN($C$22,D14)-C14+1) -> 1 | F25: =E25*D25 -> 99 | H25: =G14 -> 299 | I25: =E25*H25 -> 299
B26: =B15 -> 2 | C26: =C15&"–"&IF(D15>=9999,"+",D15) -> 4–15 | D26: =E15 -> 79 | E26: =MAX(0,MIN($C$22,D15)-C15+1) -> 0 | F26: =E26*D26 -> 0 | H26: =G15 -> 238.59596 | I26: =E26*H26 -> 0
B27: =B16 -> 3 | C27: =C16&"–"&IF(D16>=9999,"+",D16) -> 16–30 | D27: =E16 -> 69 | E27: =MAX(0,MIN($C$22,D16)-C16+1) -> 0 | F27: =E27*D27 -> 0 | H27: =G16 -> 208.39394 | I27: =E27*H27 -> 0
B28: =B17 -> 4 | C28: =C17&"–"&IF(D17>=9999,"+",D17) -> 31–50 | D28: =E17 -> 59 | E28: =MAX(0,MIN($C$22,D17)-C17+1) -> 0 | F28: =E28*D28 -> 0 | H28: =G17 -> 178.19192 | I28: =E28*H28 -> 0
B29: =B18 -> 5 | C29: =C18&"–"&IF(D18>=9999,"+",D18) -> 51–+ | D29: =E18 -> 49 | E29: =MAX(0,MIN($C$22,D18)-C18+1) -> 0 | F29: =E29*D29 -> 0 | H29: =G18 -> 147.9899 | I29: =E29*H29 -> 0
B30: Total / mo (annual-paid) | F30: =SUM(F25:F29) -> 99 | G30: =F30*12 -> 1188 | I30: =SUM(I25:I29) -> 299 | J30: =I30*12 -> 3588
B32: DEAL ECONOMICS | C32: Basic | D32: Pro
B33: Blended price / hotel / mo | C33: =$F$30/$C$22 -> 99 | D33: =$I$30/$C$22 -> 299
B34: Effective discount vs full price | C34: =1-($F$30/$C$22)/$C$6 -> 0 | D34: =1-($I$30/$C$22)/$C$11 -> 0
B35: Annual contract value / yr | C35: =$F$30*12 -> 1188 | D35: =$I$30*12 -> 3588
B36: Pay-monthly total / mo (+15%) | C36: =$F$30*(1+$C$8) -> 113.85 | D36: =$I$30*(1+$C$8) -> 343.85
B37: Blended gross margin % | C37: =1-$C$7/($F$30/$C$22) -> 0.7979798 | D37: =1-$C$7/($I$30/$C$22) -> 0.93311037
B38: Margin vs floor | C38: =IF((1-$C$7/($F$30/$C$22))<$C$10,"⚠ BELOW FLOOR","OK — healthy") -> OK — healthy | D38: =IF((1-$C$7/($I$30/$C$22))<$C$10,"⚠ BELOW FLOOR","OK — healthy") -> OK — healthy
B39: — COMPARISON —
B40: Whole-account total / mo (same deal) | C40: =$C$22*'Pricing Model'!$C$6*(1-SUMPRODUCT(($C$22>='Pricing Model'!$C$15:$C$19)*($C$22<='Pricing Model'!$D$15:$D$19)*'Pricing Model'!$E$15:$E$19)) -> 99 | D40: =$C$40*$C$11/$C$6 -> 299
B41: Graduated saves the customer | C41: =$C$22*'Pricing Model'!$C$6*(1-SUMPRODUCT(($C$22>='Pricing Model'!$C$15:$C$19)*($C$22<='Pricing Model'!$D$15:$D$19)*'Pricing Model'!$E$15:$E$19))-$F$30 -> 0 | D41: =$D$40-$I$30 -> 0
B42: Legacy total / mo (same deal) | C42: =$C$22*$C$9 -> 170
B44: SCENARIOS — Graduated vs Whole-account vs Legacy
B45: Hotels | C45: Graduated per month | D45: Grad blended per hotel | E45: Whole-acct /mo | F45: Legacy /mo | G45: Grad margin % | H45: Margin OK? | I45: Pro /mo | J45: Pro blended /hotel | K45: Pro margin %
B46: 1 | C46: =SUMPRODUCT(((((($B46+$D$14:$D$18-ABS($B46-$D$14:$D$18))/2)-$C$14:$C$18+1)+ABS(((($B46+$D$14:$D$18-ABS($B46-$D$14:$D$18))/2)-$C$14:$C$18+1)))/2)*$E$14:$E$18) -> 99 | D46: =C46/$B46 -> 99 | E46: =$B46*'Pricing Model'!$C$6*(1-SUMPRODUCT(($B46>='Pricing Model'!$C$15:$C$19)*($B46<='Pricing Model'!$D$15:$D$19)*'Pricing Model'!$E$15:$E$19)) -> 99 | F46: =$B46*$C$9 -> 170 | G46: =1-$C$7/(C46/$B46) -> 0.7979798 | H46: =IF(G46<$C$10,"⚠ LOW","OK") -> OK | I46: =SUMPRODUCT((((($B46+$D$14:$D$18-ABS($B46-$D$14:$D$18))/2)-$C$14:$C$18+1)+ABS(((($B46+$D$14:$D$18-ABS($B46-$D$14:$D$18))/2)-$C$14:$C$18+1)))/2*$G$14:$G$18) -> 299 | J46: =I46/$B46 -> 299 | K46: =1-$C$7/(I46/$B46) -> 0.93311037
...

Sheet Inclusions + Add-Ons
B5: PIXI PLATFORM - FEATURE LIST
B6: =============================
B9: HOTEL FEATURES
B10: ==============
C11: Package
C12: Listed | D12: Basic | E12: Pro | F12: Enterprise
B13: Digital Asset Management | C13: 2GB | D13: 20GB | E13: 100GB
B14: Upload documents - Upload PDFs, brochures, factsheets, logos etc. | C14: N | D14: Y | E14: Y | F14: Y
B15: AI - Built-in intelligence for your brand | C15: Y | D15: Y | E15: Y | F15: Y
B16: Downloads | C16: Unlimited | D16: Unlimited | E16: Unlimited | F16: Unlimited
B17: Additional Storage / 20GB blocks / month | C17: N/A | D17: 25 | E17: 25 | F17: 25
B18: Users / Seats | C18: 2 | D18: 15 | E18: Unlimited | F18: Unlimited
B19: Data Insights | C19: N | D19: Y | E19: Y
B20: Showcases - shareable live galleries | C20: 1 | D20: 15 | E20: Unlimited | F20: Unlimited
B21: Personalised (Showcases - Branded) | C21: N | D21: N | E21: Y | F21: Y
B24: DAM ( Digital Asset Management ) | C24: Limited | D24: Y | E24: Y | F24: Y
B25: Storage - the more you store and publish, the more exposure you receive to the network | C25: 2GB | D25: 25GM | E25: 100GM | F25: Unlimited
B26: Folders - Create, rename, delete and organise media into custom folders | C26: Limited | D26: Y | E26: Y | F26: Y
B27: Search & sort - Search by keyword, sort by date/name/size, filter by type | C27: Y | D27: Y | E27: Y | F27: Y
B28: Publish / draft - Control which assets are visible to agents, bulk publish or unpublish | C28: Y | D28: Y | E28: Y | F28: Y
B29: Media metadata - View format, resolution, file size, upload date for each asset | C29: Y | D29: Y | E29: Y | F29: Y
B30: Bulk operations - Bulk update, move, delete, publish, unpublish assets in one go | C30: Y | D30: Y | E30: Y | F30: Y
B31: Usage restrictions - Tag media with usage rules (social only, print only, etc.) and custom restrictions | C31: Y | D31: Y | E31: Y | F31: Y
B32: Document folders - Organise documents into folders, same as media | C32: N | D32: Y | E32: Y | F32: Y
B33: Internal Documents - Add documents that are not visible to Agents | C33: N | D33: Y | E33: Y | F33: Y
B34: Attach to showcases - Add documents to showcases | C34: N | D34: Y | E34: Y | F34: Y
... B39: Showcase analytics - Track views and engagement on each showcase | C39: Y | D39: Y | E39: Y | F39: Y
B40: Distribution
B41: Distribution to elite travel advisor network | C41: Limited | D41: Y | E41: Y | F41: Y
B42: Searchable with intelligent search | C42: Y | D42: Y | E42: Y | F42: Y
B43: Featured exposure | C43: N | D43: Y | E43: Y | F43: Y
B44: Analytics
B45: Summary stats - See total downloads, total impressions | C45: N | D45: Y | E45: Y | F45: Y
B46: Partner management - View interactions from agencies and visit their profiles | C46: N | D46: Y | E46: Y | F46: Y
B47: Block/unblock agents - Control which agencies can access your property | C47: N | D47: Y | E47: Y | F47: Y
B48: Export reports - Download CSV of your most engaged travel advisors | C48: N | D48: Y | E48: Y | F48: Y
B49: View your best performing content | C49: N | D49: Y | E49: Y | F49: Y

Sheet Pricing Model
B2: PIXI — Merged Pricing Model
B3: REFERENCE / comparison only (whole-account discount). Adopted model is the Graduated tab. NOTE: this tab holds the shared assumptions (base, cost, uplift, benchmark, floor) that feed BOTH models — edit them here.
B5: GLOBAL ASSUMPTIONS (blue = edit me)
B6: Base price / hotel / mo (billed annually) | C6: 99 | D6: Single flat headline — the no-brainer entry, before group discount
B7: CAC per deal (£) | C7: 500 | D7: One sales deal acquires the whole group
B8: Monthly-billing uplift | C8: 0.15 | D8: Pay monthly = annual rate + 15%
B9: Current benchmark / hotel / mo (annual-paid) | C9: 170 | D9: Legacy Small = £170/mo; Medium/Large climb to £425/£595 per hotel
B10: Cost to serve / hotel / mo (£) | C10: 20 | D10: Hosting, verification & content refresh — your marginal cost
B11: Margin floor — flag below | C11: 0.6 | D11: Gross-margin alarm — any rate below this gets flagged
B13: WHOLE-ACCOUNT VOLUME DISCOUNT (1–3 full price · group discount from 4 · cliff-free)
B14: Band | C14: From (hotels) | D14: To (hotels) | E14: Discount % | F14: Annual-paid £/mo
B15: 1 | C15: 1 | D15: 3 | E15: 0 | F15: =$C$6*(1-E15) -> 99
B16: 2 | C16: 4 | D16: 15 | E16: 0.22 | F16: =$C$6*(1-E16) -> 77.22
B17: 3 | C17: 16 | D17: 30 | E17: 0.26 | F17: =$C$6*(1-E17) -> 73.26
B18: 4 | C18: 31 | D18: 50 | E18: 0.28 | F18: =$C$6*(1-E18) -> 71.28
B19: 5 | C19: 51 | D19: 9999 | E19: 0.29 | F19: =$C$6*(1-E19) -> 70.29
B20: 1–3 hotels pay full price; group discount begins at 4. Depth is capped to stay cliff-free (see Cliff Check). 51+ = bespoke.
B23: CLIFF CHECK (does the annual-paid total ever FALL when a hotel is added?)
B24: Threshold (hotels) | C24: Total at N-1 | D24: Total at N | E24: Status
B25: =C16 -> 4 | C25: =(C16-1)*$C$6*(1-E15) -> 297 | D25: =C16*$C$6*(1-E16) -> 308.88 | E25: =IF(D25<C25,"⚠ CLIFF","OK") -> OK
B26: =C17 -> 16 | C26: =(C17-1)*$C$6*(1-E16) -> 1158.3 | D26: =C17*$C$6*(1-E17) -> 1172.16 | E26: =IF(D26<C26,"⚠ CLIFF","OK") -> OK
B27: =C18 -> 31 | C27: =(C18-1)*$C$6*(1-E17) -> 2197.8 | D27: =C18*$C$6*(1-E18) -> 2209.68 | E27: =IF(D27<C27,"⚠ CLIFF","OK") -> OK
B28: =C19 -> 51 | C28: =(C19-1)*$C$6*(1-E18) -> 3564 | D28: =C19*$C$6*(1-E19) -> 3584.79 | E28: =IF(D28<C28,"⚠ CLIFF","OK") -> OK
B31: INCLUDED PER HOTEL + EXPANSION BLOCKS (Dash-style)
B32: Included storage / hotel (GB) | C32: 25
B33: Downloads | C33: Unlimited (fair use)
B34: Seats | C34: Unlimited
B35: Extra storage block (per 25GB, £/mo) | C35: 25
B36: Property film / video pack (£/mo) | C36: 25
B38: QUOTE CALCULATOR (enter a deal → see economics)
B39: Number of hotels in deal | C39: 5
B40: Applicable discount | C40: =SUMPRODUCT(($C$39>=$C$15:$C$19)*($C$39<=$D$15:$D$19)*$E$15:$E$19) -> 0.22
B41: Annual-paid price / hotel / mo | C41: =$C$6*(1-SUMPRODUCT(($C$39>=$C$15:$C$19)*($C$39<=$D$15:$D$19)*$E$15:$E$19)) -> 77.22
B42: Base total / mo (annual-paid) | C42: =$C$39*$C$6*(1-SUMPRODUCT(($C$39>=$C$15:$C$19)*($C$39<=$D$15:$D$19)*$E$15:$E$19)) -> 386.1
B44: OPTIONAL ADD-ON BLOCKS (whole account, flat £/mo)
B45: Extra storage blocks (qty) | C45: 1 | D45: =C45*$C$35 -> 25
B46: Video packs (qty) | C46: 0 | D46: =C46*$C$36 -> 0
B47: Add-on total (£/mo) | D47: =SUM(D45:D46) -> 25
B49: DEAL ECONOMICS
B50: Applicable discount | C50: =SUMPRODUCT(($C$39>=$C$15:$C$19)*($C$39<=$D$15:$D$19)*$E$15:$E$19) -> 0.22
...

Sheet Group Scenarios
B2: Group Scenarios — price, savings & live gross margin
B3: Whole-account scenarios (reference). The adopted Graduated model's own scenarios & comparison live on the 'Graduated Pricing' tab.
B5: Hotels | C5: Discount % | D5: Annual-paid /hotel /mo | E5: Annual contract value /yr | F5: Pay-monthly /hotel /mo | G5: Legacy annual /yr | H5: Annual saving /yr | I5: Saving % | J5: Rises? | K5: Gross margin % | L5: Floor | M5: Margin OK? | N5: Sig annual-paid /hotel /mo | O5: Sig ACV /yr | P5: Sig gross margin % | Q5: Sig margin OK?
B6: 1 | C6: =SUMPRODUCT(($B6>='Pricing Model'!$C$15:$C$19)*($B6<='Pricing Model'!$D$15:$D$19)*'Pricing Model'!$E$15:$E$19) -> 0 | D6: ='Pricing Model'!$C$6*(1-C6) -> 99 | E6: =$B6*D6*12 -> 1188 | F6: =D6*(1+'Pricing Model'!$C$8) -> 113.85 | G6: =$B6*'Pricing Model'!$C$9*12 -> 2040 | H6: =G6-E6 -> 852 | I6: =IF(G6=0,0,1-E6/G6) -> 0.41764706 | J6: — | K6: =1-'Pricing Model'!$C$10/D6 -> 0.7979798 | L6: ='Pricing Model'!$C$11 -> 0.6 | M6: =IF(K6<L6,"⚠ LOW","OK") -> OK | N6: =D6*'Graduated Pricing'!$C$11/'Pricing Model'!$C$6 -> 299 | O6: =$B6*N6*12 -> 3588 | P6: =1-'Pricing Model'!$C$10/N6 -> 0.93311037 | Q6: =IF(P6<L6,"⚠ LOW","OK") -> OK
B7: 2 | C7: =SUMPRODUCT(($B7>='Pricing Model'!$C$15:$C$19)*($B7<='Pricing Model'!$D$15:$D$19)*'Pricing Model'!$E$15:$E$19) -> 0 | D7: ='Pricing Model'!$C$6*(1-C7) -> 99 | E7: =$B7*D7*12 -> 2376 | F7: =D7*(1+'Pricing Model'!$C$8) -> 113.85 | G7: =$B7*'Pricing Model'!$C$9*12 -> 4080 | H7: =G7-E7 -> 1704 | I7: =IF(G7=0,0,1-E7/G7) -> 0.41764706 | J7: =IF(E7>=E6,"OK","⚠ CLIFF") -> OK | K7: =1-'Pricing Model'!$C$10/D7 -> 0.7979798 | L7: ='Pricing Model'!$C$11 -> 0.6 | M7: =IF(K7<L7,"⚠ LOW","OK") -> OK | N7: =D7*'Graduated Pricing'!$C$11/'Pricing Model'!$C$6 -> 299 | O7: =$B7*N7*12 -> 7176 | P7: =1-'Pricing Model'!$C$10/N7 -> 0.93311037 | Q7: =IF(P7<L7,"⚠ LOW","OK") -> OK
B8: 3 | C8: =SUMPRODUCT(($B8>='Pricing Model'!$C$15:$C$19)*($B8<='Pricing Model'!$D$15:$D$19)*'Pricing Model'!$E$15:$E$19) -> 0 | D8: ='Pricing Model'!$C$6*(1-C8) -> 99 | E8: =$B8*D8*12 -> 3564 | F8: =D8*(1+'Pricing Model'!$C$8) -> 113.85 | G8: =$B8*'Pricing Model'!$C$9*12 -> 6120 | H8: =G8-E8 -> 2556 | I8: =IF(G8=0,0,1-E8/G8) -> 0.41764706 | J8: =IF(E8>=E7,"OK","⚠ CLIFF") -> OK | K8: =1-'Pricing Model'!$C$10/D8 -> 0.7979798 | L8: ='Pricing Model'!$C$11 -> 0.6 | M8: =IF(K8<L8,"⚠ LOW","OK") -> OK | N8: =D8*'Graduated Pricing'!$C$11/'Pricing Model'!$C$6 -> 299 | O8: =$B8*N8*12 -> 10764 | P8: =1-'Pricing Model'!$C$10/N8 -> 0.93311037 | Q8: =IF(P8<L8,"⚠ LOW","OK") -> OK
B9: 4 | C9: =SUMPRODUCT(($B9>='Pricing Model'!$C$15:$C$19)*($B9<='Pricing Model'!$D$15:$D$19)*'Pricing Model'!$E$15:$E$19) -> 0.22 | D9: ='Pricing Model'!$C$6*(1-C9) -> 77.22 | E9: =$B9*D9*12 -> 3706.56 | F9: =D9*(1+'Pricing Model'!$C$8) -> 88.803 | G9: =$B9*'Pricing Model'!$C$9*12 -> 8160 | H9: =G9-E9 -> 4453.44 | I9: =IF(G9=0,0,1-E9/G9) -> 0.54576471 | J9: =IF(E9>=E8,"OK","⚠ CLIFF") -> OK | K9: =1-'Pricing Model'!$C$10/D9 -> 0.74099974 | L9: ='Pricing Model'!$C$11 -> 0.6 | M9: =IF(K9<L9,"⚠ LOW","OK") -> OK | N9: =D9*'Graduated Pricing'!$C$11/'Pricing Model'!$C$6 -> 233.22 | O9: =$B9*N9*12 -> 11194.56 | P9: =1-'Pricing Model'!$C$10/N9 -> 0.91424406 | Q9: =IF(P9<L9,"⚠ LOW","OK") -> OK
B10: 5 | C10: =SUMPRODUCT(($B10>='Pricing Model'!$C$15:$C$19)*($B10<='Pricing Model'!$D$15:$D$19)*'Pricing Model'!$E$15:$E$19) -> 0.22 | D10: ='Pricing Model'!$C$6*(1-C10) -> 77.22 | E10: =$B10*D10*12 -> 4633.2 | F10: =D10*(1+'Pricing Model'!$C$8) -> 88.803 | G10: =$B10*'Pricing Model'!$C$9*12 -> 10200 | H10: =G10-E10 -> 5566.8 | I10: =IF(G10=0,0,1-E10/G10) -> 0.54576471 | J10: =IF(E10>=E9,"OK","⚠ CLIFF") -> OK | K10: =1-'Pricing Model'!$C$10/D10 -> 0.74099974 | L10: ='Pricing Model'!$C$11 -> 0.6 | M10: =IF(K10<L10,"⚠ LOW","OK") -> OK | N10: =D10*'Graduated Pricing'!$C$11/'Pricing Model'!$C$6 -> 233.22 | O10: =$B10*N10*12 -> 13993.2 | P10: =1-'Pricing Model'!$C$10/N10 -> 0.91424406 | Q10: =IF(P10<L10,"⚠ LOW","OK") -> OK
B11: 10 | C11: =SUMPRODUCT(($B11>='Pricing Model'!$C$15:$C$19)*($B11<='Pricing Model'!$D$15:$D$19)*'Pricing Model'!$E$15:$E$19) -> 0.22 | D11: ='Pricing Model'!$C$6*(1-C11) -> 77.22 | E11: =$B11*D11*12 -> 9266.4 | F11: =D11*(1+'Pricing Model'!$C$8) -> 88.803 | G11: =$B11*'Pricing Model'!$C$9*12 -> 20400 | H11: =G11-E11 -> 11133.6 | I11: =IF(G11=0,0,1-E11/G11) -> 0.54576471 | J11: =IF(E11>=E10,"OK","⚠ CLIFF") -> OK | K11: =1-'Pricing Model'!$C$10/D11 -> 0.74099974 | L11: ='Pricing Model'!$C$11 -> 0.6 | M11: =IF(K11<L11,"⚠ LOW","OK") -> OK | N11: =D11*'Graduated Pricing'!$C$11/'Pricing Model'!$C$6 -> 233.22 | O11: =$B11*N11*12 -> 27986.4 | P11: =1-'Pricing Model'!$C$10/N11 -> 0.91424406 | Q11: =IF(P11<L11,"⚠ LOW","OK") -> OK
B12: 15 | C12: =SUMPRODUCT(($B12>='Pricing Model'!$C$15:$C$19)*($B12<='Pricing Model'!$D$15:$D$19)*'Pricing Model'!$E$15:$E$19) -> 0.22 | D12: ='Pricing Model'!$C$6*(1-C12) -> 77.22 | E12: =$B12*D12*12 -> 13899.6 | F12: =D12*(1+'Pricing Model'!$C$8) -> 88.803 | G12: =$B12*'Pricing Model'!$C$9*12 -> 30600 | H12: =G12-E12 -> 16700.4 | I12: =IF(G12=0,0,1-E12/G12) -> 0.54576471 | J12: =IF(E12>=E11,"OK","⚠ CLIFF") -> OK | K12: =1-'Pricing Model'!$C$10/D12 -> 0.74099974 | L12: ='Pricing Model'!$C$11 -> 0.6 | M12: =IF(K12<L12,"⚠ LOW","OK") -> OK | N12: =D12*'Graduated Pricing'!$C$11/'Pricing Model'!$C$6 -> 233.22 | O12: =$B12*N12*12 -> 41979.6 | P12: =1-'Pricing Model'!$C$10/N12 -> 0.91424406 | Q12: =IF(P12<L12,"⚠ LOW","OK") -> OK
B13: 20 | C13: =SUMPRODUCT(($B13>='Pricing Model'!$C$15:$C$19)*($B13<='Pricing Model'!$D$15:$D$19)*'Pricing Model'!$E$15:$E$19) -> 0.26 | D13: ='Pricing Model'!$C$6*(1-C13) -> 73.26 | E13: =$B13*D13*12 -> 17582.4 | F13: =D13*(1+'Pricing Model'!$C$8) -> 84.249 | G13: =$B13*'Pricing Model'!$C$9*12 -> 40800 | H13: =G13-E13 -> 23217.6 | I13: =IF(G13=0,0,1-E13/G13) -> 0.56905882 | J13: =IF(E13>=E12,"OK","⚠ CLIFF") -> OK | K13: =1-'Pricing Model'!$C$10/D13 -> 0.72699973 | L13: ='Pricing Model'!$C$11 -> 0.6 | M13: =IF(K13<L13,"⚠ LOW","OK") -> OK | N13: =D13*'Graduated Pricing'!$C$11/'Pricing Model'!$C$6 -> 221.26 | O13: =$B13*N13*12 -> 53102.4 | P13: =1-'Pricing Model'!$C$10/N13 -> 0.90960861 | Q13: =IF(P13<L13,"⚠ LOW","OK") -> OK
B14: 30 | C14: =SUMPRODUCT(($B14>='Pricing Model'!$C$15:$C$19)*($B14<='Pricing Model'!$D$15:$D$19)*'Pricing Model'!$E$15:$E$19) -> 0.26 | D14: ='Pricing Model'!$C$6*(1-C14) -> 73.26 | E14: =$B14*D14*12 -> 26373.6 | F14: =D14*(1+'Pricing Model'!$C$8) -> 84.249 | G14: =$B14*'Pricing Model'!$C$9*12 -> 61200 | H14: =G14-E14 -> 34826.4 | I14: =IF(G14=0,0,1-E14/G14) -> 0.56905882 | J14: =IF(E14>=E13,"OK","⚠ CLIFF") -> OK | K14: =1-'Pricing Model'!$C$10/D14 -> 0.72699973 | L14: ='Pricing Model'!$C$11 -> 0.6 | M14: =IF(K14<L14,"⚠ LOW","OK") -> OK | N14: =D14*'Graduated Pricing'!$C$11/'Pricing Model'!$C$6 -> 221.26 | O14: =$B14*N14*12 -> 79653.6 | P14: =1-'Pricing Model'!$C$10/N14 -> 0.90960861 | Q14: =IF(P14<L14,"⚠ LOW","OK") -> OK
B15: 50 | C15: =SUMPRODUCT(($B15>='Pricing Model'!$C$15:$C$19)*($B15<='Pricing Model'!$D$15:$D$19)*'Pricing Model'!$E$15:$E$19) -> 0.28 | D15: ='Pricing Model'!$C$6*(1-C15) -> 71.28 | E15: =$B15*D15*12 -> 42768 | F15: =D15*(1+'Pricing Model'!$C$8) -> 81.972 | G15: =$B15*'Pricing Model'!$C$9*12 -> 102000 | H15: =G15-E15 -> 59232 | I15: =IF(G15=0,0,1-E15/G15) -> 0.58070588 | J15: =IF(E15>=E14,"OK","⚠ CLIFF") -> OK | K15: =1-'Pricing Model'!$C$10/D15 -> 0.71941639 | L15: ='Pricing Model'!$C$11 -> 0.6 | M15: =IF(K15<L15,"⚠ LOW","OK") -> OK | N15: =D15*'Graduated Pricing'!$C$11/'Pricing Model'!$C$6 -> 215.28 | O15: =$B15*N15*12 -> 129168 | P15: =1-'Pricing Model'!$C$10/N15 -> 0.90709773 | Q15: =IF(P15<L15,"⚠ LOW","OK") -> OK
B16: 75 | C16: =SUMPRODUCT(($B16>='Pricing Model'!$C$15:$C$19)*($B16<='Pricing Model'!$D$15:$D$19)*'Pricing Model'!$E$15:$E$19) -> 0.29 | D16: ='Pricing Model'!$C$6*(1-C16) -> 70.29 | E16: =$B16*D16*12 -> 63261 | F16: =D16*(1+'Pricing Model'!$C$8) -> 80.8335 | G16: =$B16*'Pricing Model'!$C$9*12 -> 153000 | H16: =G16-E16 -> 89739 | I16: =IF(G16=0,0,1-E16/G16) -> 0.58652941 | J16: =IF(E16>=E15,"OK","⚠ CLIFF") -> OK | K16: =1-'Pricing Model'!$C$10/D16 -> 0.7154645 | L16: ='Pricing Model'!$C$11 -> 0.6 | M16: =IF(K16<L16,"⚠ LOW","OK") -> OK | N16: =D16*'Graduated Pricing'!$C$11/'Pricing Model'!$C$6 -> 212.29 | O16: =$B16*N16*12 -> 191061 | P16: =1-'Pricing Model'!$C$10/N16 -> 0.90578925 | Q16: =IF(P16<L16,"⚠ LOW","OK") -> OK
B17: 100 | C17: =SUMPRODUCT(($B17>='Pricing Model'!$C$15:$C$19)*($B17<='Pricing Model'!$D$15:$D$19)*'Pricing Model'!$E$15:$E$19) -> 0.29 | D17: ='Pricing Model'!$C$6*(1-C17) -> 70.29 | E17: =$B17*D17*12 -> 84348 | F17: =D17*(1+'Pricing Model'!$C$8) -> 80.8335 | G17: =$B17*'Pricing Model'!$C$9*12 -> 204000 | H17: =G17-E17 -> 119652 | I17: =IF(G17=0,0,1-E17/G17) -> 0.58652941 | J17: =IF(E17>=E16,"OK","⚠ CLIFF") -> OK | K17: =1-'Pricing Model'!$C$10/D17 -> 0.7154645 | L17: ='Pricing Model'!$C$11 -> 0.6 | M17: =IF(K17<L17,"⚠ LOW","OK") -> OK | N17: =D17*'Graduated Pricing'!$C$11/'Pricing Model'!$C$6 -> 212.29 | O17: =$B17*N17*12 -> 254748 | P17: =1-'Pricing Model'!$C$10/N17 -> 0.90578925 | Q17: =IF(P17<L17,"⚠ LOW","OK") -> OK

Sheet Revenue Forecast
B2: PIXI — Revenue Forecast (Jul 2026 → Dec 2027)
B3: Forecasts a MIX of Essentials (£99) and Signature (£299) deals. Both priced on the adopted graduated model; set the Signature share of new deals to model the mix. Exit ARR flexes with the split — see Mix Sensitivity below.
B5: FORECAST ASSUMPTIONS (blue = edit me)
B6: Starting MRR today (£/mo) | C6: 15500 | D6: ← current recurring book; 0 = build from scratch
B7: New deals won — month 1 (Jul-26) | C7: 3 | D7: ← a deal = one account, 1..N hotels
B8: Monthly growth in new deals won | C8: 0.15 | D8: ← compounding ramp on deals won each month
B9: Avg hotels per new deal | C9: 3 | D9: ← drives the graduated group discount
B10: Signature share of new deals | C10: 0.25 | D10: ← THE MIX LEVER: % of new deals on Signature
B11: Share of new deals billed monthly | C11: 0.1 | D11: ← monthly billing = +15% vs annual-paid
B12: Monthly revenue churn | C12: 0.05 | D12: ← applied to the existing base each month
B14: TIER PRICING (per hotel / mo, annual-paid — graduated group discount applies to both)
B15: Essentials anchor (hotel 1–3) | C15: ='Pricing Model'!$C$6 -> 99 | D15: ← linked from Pricing Model
B16: Signature anchor (hotel 1–3) | C16: ='Graduated Pricing'!$C$11 -> 299 | D16: ← Signature anchor (master lives on Graduated tab; edit it there)
B17: Signature vs Essentials multiple | C17: =$C$16/$C$15 -> 3.020202 | D17: sanity check on the step-up
B18: Monthly-billing uplift | C18: ='Pricing Model'!$C$8 -> 0.15 | D18: ← linked from Pricing Model
B20: DERIVED PER-DEAL ECONOMICS (at avg hotels/deal, live from graduated model)
B21: Essentials — graduated total / deal / mo (annual) | C21: =SUMPRODUCT((((( $C$9+'Graduated Pricing'!$D$14:$D$18-ABS($C$9-'Graduated Pricing'!$D$14:$D$18))/2)-'Graduated Pricing'!$C$14:$C$18+1)+ABS((($C$9+'Graduated Pricing'!$D$14:$D$18-ABS($C$9-'Graduated Pricing'!$D$14:$D$18))/2-'Graduated Pricing'!$C$14:$C$18+1)))/2*'Graduated Pricing'!$E$14:$E$18) -> 297
B22: Essentials blended rate / hotel / mo | C22: =$C$21/$C$9 -> 99
B23: Signature blended rate / hotel / mo | C23: =$C$22*$C$16/$C$15 -> 299
B24: Essentials MRR / deal (annual+monthly mix) | C24: =$C$21*(1+$C$11*$C$18) -> 301.455
B25: Signature MRR / deal (annual+monthly mix) | C25: =$C$21*($C$16/$C$15)*(1+$C$11*$C$18) -> 910.455
B26: Blended MRR / new deal (at current mix) | C26: =(1-$C$10)*$C$24+$C$10*$C$25 -> 453.705
B28: MONTHLY BUILD (18 months · Jul-26 → Dec-27)
B29: Month | C29: New deals | D29: Sig deals | E29: New Ess MRR | F29: New Sig MRR | G29: Total New MRR | H29: Opening MRR | I29: Churn | J29: Ending MRR | K29: Decay→exit
B30: Jul-26 | C30: =ROUND($C$7*(1+$C$8)^0,0) -> 3 | D30: =C30*$C$10 -> 0.75 | E30: =C30*(1-$C$10)*$C$24 -> 678.27375 | F30: =C30*$C$10*$C$25 -> 682.84125 | G30: =E30+F30 -> 1361.115 | H30: =$C$6 -> 15500 | I30: =H30*$C$12 -> 775 | J30: =H30+G30-I30 -> 16086.115 | K30: =(1-$C$12)^17 -> 0.41812034
B31: Aug-26 | C31: =ROUND($C$7*(1+$C$8)^1,0) -> 3 | D31: =C31*$C$10 -> 0.75 | E31: =C31*(1-$C$10)*$C$24 -> 678.27375 | F31: =C31*$C$10*$C$25 -> 682.84125 | G31: =E31+F31 -> 1361.115 | H31: =J30 -> 16086.115 | I31: =H31*$C$12 -> 804.30575 | J31: =H31+G31-I31 -> 16642.924 | K31: =(1-$C$12)^16 -> 0.44012667
B32: Sep-26 | C32: =ROUND($C$7*(1+$C$8)^2,0) -> 4 | D32: =C32*$C$10 -> 1 | E32: =C32*(1-$C$10)*$C$24 -> 904.365 | F32: =C32*$C$10*$C$25 -> 910.455 | G32: =E32+F32 -> 1814.82 | H32: =J31 -> 16642.924 | I32: =H32*$C$12 -> 832.14621 | J32: =H32+G32-I32 -> 17625.598 | K32: =(1-$C$12)^15 -> 0.46329123
B33: Oct-26 | C33: =ROUND($C$7*(1+$C$8)^3,0) -> 5 | D33: =C33*$C$10 -> 1.25 | E33: =C33*(1-$C$10)*$C$24 -> 1130.4562 | F33: =C33*$C$10*$C$25 -> 1138.0687 | G33: =E33+F33 -> 2268.525 | H33: =J32 -> 17625.598 | I33: =H33*$C$12 -> 881.2799 | J33: =H33+G33-I33 -> 19012.843 | K33: =(1-$C$12)^14 -> 0.48767498
B34: Nov-26 | C34: =ROUND($C$7*(1+$C$8)^4,0) -> 5 | D34: =C34*$C$10 -> 1.25 | E34: =C34*(1-$C$10)*$C$24 -> 1130.4562 | F34: =C34*$C$10*$C$25 -> 1138.0687 | G34: =E34+F34 -> 2268.525 | H34: =J33 -> 19012.843 | I34: =H34*$C$12 -> 950.64216 | J34: =H34+G34-I34 -> 20330.726 | K34: =(1-$C$12)^13 -> 0.51334208
B35: Dec-26 | C35: =ROUND($C$7*(1+$C$8)^5,0) -> 6 | D35: =C35*$C$10 -> 1.5 | E35: =C35*(1-$C$10)*$C$24 -> 1356.5475 | F35: =C35*$C$10*$C$25 -> 1365.6825 | G35: =E35+F35 -> 2722.23 | H35: =J34 -> 20330.726 | I35: =H35*$C$12 -> 1016.5363 | J35: =H35+G35-I35 -> 22036.42 | K35: =(1-$C$12)^12 -> 0.54036009
B36: Jan-27 | C36: =ROUND($C$7*(1+$C$8)^6,0) -> 7 | D36: =C36*$C$10 -> 1.75 | E36: =C36*(1-$C$10)*$C$24 -> 1582.6387 | F36: =C36*$C$10*$C$25 -> 1593.2962 | G36: =E36+F36 -> 3175.935 | H36: =J35 -> 22036.42 | I36: =H36*$C$12 -> 1101.821 | J36: =H36+G36-I36 -> 24110.534 | K36: =(1-$C$12)^11 -> 0.56880009
B37: Feb-27 | C37: =ROUND($C$7*(1+$C$8)^7,0) -> 8 | D37: =C37*$C$10 -> 2 | E37: =C37*(1-$C$10)*$C$24 -> 1808.73 | F37: =C37*$C$10*$C$25 -> 1820.91 | G37: =E37+F37 -> 3629.64 | H37: =J36 -> 24110.534 | I37: =H37*$C$12 -> 1205.5267 | J37: =H37+G37-I37 -> 26534.647 | K37: =(1-$C$12)^10 -> 0.59873694
B38: Mar-27 | C38: =ROUND($C$7*(1+$C$8)^8,0) -> 9 | D38: =C38*$C$10 -> 2.25 | E38: =C38*(1-$C$10)*$C$24 -> 2034.8212 | F38: =C38*$C$10*$C$25 -> 2048.5237 | G38: =E38+F38 -> 4083.345 | H38: =J37 -> 26534.647 | I38: =H38*$C$12 -> 1326.7324 | J38: =H38+G38-I38 -> 29291.26 | K38: =(1-$C$12)^9 -> 0.63024941
B39: Apr-27 | C39: =ROUND($C$7*(1+$C$8)^9,0) -> 11 | D39: =C39*$C$10 -> 2.75 | E39: =C39*(1-$C$10)*$C$24 -> 2487.0037 | F39: =C39*$C$10*$C$25 -> 2503.7512 | G39: =E39+F39 -> 4990.755 | H39: =J38 -> 29291.26 | I39: =H39*$C$12 -> 1464.563 | J39: =H39+G39-I39 -> 32817.452 | K39: =(1-$C$12)^8 -> 0.66342043
B40: May-27 | C40: =ROUND($C$7*(1+$C$8)^10,0) -> 12 | D40: =C40*$C$10 -> 3 | E40: =C40*(1-$C$10)*$C$24 -> 2713.095 | F40: =C40*$C$10*$C$25 -> 2731.365 | G40: =E40+F40 -> 5444.46 | H40: =J39 -> 32817.452 | I40: =H40*$C$12 -> 1640.8726 | J40: =H40+G40-I40 -> 36621.039 | K40: =(1-$C$12)^7 -> 0.6983373
B41: Jun-27 | C41: =ROUND($C$7*(1+$C$8)^11,0) -> 14 | D41: =C41*$C$10 -> 3.5 | E41: =C41*(1-$C$10)*$C$24 -> 3165.2775 | F41: =C41*$C$10*$C$25 -> 3186.5925 | G41: =E41+F41 -> 6351.87 | H41: =J40 -> 36621.039 | I41: =H41*$C$12 -> 1831.052 | J41: =H41+G41-I41 -> 41141.857 | K41: =(1-$C$12)^6 -> 0.73509189
B42: Jul-27 | C42: =ROUND($C$7*(1+$C$8)^12,0) -> 16 | D42: =C42*$C$10 -> 4 | E42: =C42*(1-$C$10)*$C$24 -> 3617.46 | F42: =C42*$C$10*$C$25 -> 3641.82 | G42: =E42+F42 -> 7259.28 | H42: =J41 -> 41141.857 | I42: =H42*$C$12 -> 2057.0929 | J42: =H42+G42-I42 -> 46344.044 | K42: =(1-$C$12)^5 -> 0.77378094
B43: Aug-27 | C43: =ROUND($C$7*(1+$C$8)^13,0) -> 18 | D43: =C43*$C$10 -> 4.5 | E43: =C43*(1-$C$10)*$C$24 -> 4069.6425 | F43: =C43*$C$10*$C$25 -> 4097.0475 | G43: =E43+F43 -> 8166.69 | H43: =J42 -> 46344.044 | I43: =H43*$C$12 -> 2317.2022 | J43: =H43+G43-I43 -> 52193.532 | K43: =(1-$C$12)^4 -> 0.81450625
B44: Sep-27 | C44: =ROUND($C$7*(1+$C$8)^14,0) -> 21 | D44: =C44*$C$10 -> 5.25 | E44: =C44*(1-$C$10)*$C$24 -> 4747.9162 | F44: =C44*$C$10*$C$25 -> 4779.8888 | G44: =E44+F44 -> 9527.805 | H44: =J43 -> 52193.532 | I44: =H44*$C$12 -> 2609.6766 | J44: =H44+G44-I44 -> 59111.66 | K44: =(1-$C$12)^3 -> 0.857375
B45: Oct-27 | C45: =ROUND($C$7*(1+$C$8)^15,0) -> 24 | D45: =C45*$C$10 -> 6 | E45: =C45*(1-$C$10)*$C$24 -> 5426.19 | F45: =C45*$C$10*$C$25 -> 5462.73 | G45: =E45+F45 -> 10888.92 | H45: =J44 -> 59111.66 | I45: =H45*$C$12 -> 2955.583 | J45: =H45+G45-I45 -> 67044.997 | K45: =(1-$C$12)^2 -> 0.9025
...

Sheet Notes & Sources
B2: Model Logic, Assumptions & Sources
B3: ADOPTED MODEL — GRADUATED (TAX-BRACKET) PRICING
B4: • PIXI prices per hotel using graduated brackets, like income tax. The first 3 hotels always pay the full £99;
B5: each higher bracket (4–15, 16–30, 31–50, 51+) bills at a lower MARGINAL rate. An account's total is the sum of
B6: its brackets, so it is cliff-free by construction — the total always rises as hotels are added.
B7: • Default marginal rates: £99 / £69 / £54 / £44 / £39 per hotel per bracket (all editable, blue, on the Graduated tab).
B9: HOW TO USE IT (engine vs pitch)
B10: • Graduated is the internal deal-desk ENGINE. Customers never need to see the brackets.
B11: • Quote them the blended per-hotel rate + the monthly/annual total, e.g. '20 hotels, £1,395/mo, ~£70/hotel'.
B12: • Pay monthly = annual-paid rate + 15%. Storage blocks & video packs are near-pure margin on top.
B14: WHY GRADUATED (vs whole-account)
B15: • Protects margin on small groups — a 4–10 hotel deal keeps its first 3 hotels at full price instead of
... B31: Colour key: blue = input you edit · black = formula · green = pulled from another sheet
